Traceback (most recent call last):
  File "/home/runner/micromamba-root/envs/docs/lib/python3.10/site-packages/jupyter_cache/executors/utils.py", line 58, in single_nb_execution
    executenb(
  File "/home/runner/micromamba-root/envs/docs/lib/python3.10/site-packages/nbclient/client.py", line 1305, in execute
    return NotebookClient(nb=nb, resources=resources, km=km, **kwargs).execute()
  File "/home/runner/micromamba-root/envs/docs/lib/python3.10/site-packages/jupyter_core/utils/__init__.py", line 166, in wrapped
    return loop.run_until_complete(inner)
  File "/home/runner/micromamba-root/envs/docs/lib/python3.10/asyncio/base_events.py", line 641, in run_until_complete
    return future.result()
  File "/home/runner/micromamba-root/envs/docs/lib/python3.10/site-packages/nbclient/client.py", line 705, in async_execute
    await self.async_execute_cell(
  File "/home/runner/micromamba-root/envs/docs/lib/python3.10/site-packages/nbclient/client.py", line 1058, in async_execute_cell
    await self._check_raise_for_error(cell, cell_index, exec_reply)
  File "/home/runner/micromamba-root/envs/docs/lib/python3.10/site-packages/nbclient/client.py", line 914, in _check_raise_for_error
    raise CellExecutionError.from_cell_and_msg(cell, exec_reply_content)
nbclient.exceptions.CellExecutionError: An error occurred while executing the following cell:
------------------
my_gnm = oenm.GaussianNetworkModel('1V4T', selection='atom_name=="CA"', cutoff='7.0 angstroms')
------------------


[0;31m---------------------------------------------------------------------------[0m
[0;31mTypeError[0m                                 Traceback (most recent call last)
Cell [0;32mIn[2], line 1[0m
[0;32m----> 1[0m my_gnm [38;5;241m=[39m [43moenm[49m[38;5;241;43m.[39;49m[43mGaussianNetworkModel[49m[43m([49m[38;5;124;43m'[39;49m[38;5;124;43m1V4T[39;49m[38;5;124;43m'[39;49m[43m,[49m[43m [49m[43mselection[49m[38;5;241;43m=[39;49m[38;5;124;43m'[39;49m[38;5;124;43matom_name==[39;49m[38;5;124;43m"[39;49m[38;5;124;43mCA[39;49m[38;5;124;43m"[39;49m[38;5;124;43m'[39;49m[43m,[49m[43m [49m[43mcutoff[49m[38;5;241;43m=[39;49m[38;5;124;43m'[39;49m[38;5;124;43m7.0 angstroms[39;49m[38;5;124;43m'[39;49m[43m)[49m

File [0;32m~/micromamba-root/envs/docs/lib/python3.10/site-packages/openenm/gaussian_network_model.py:34[0m, in [0;36mGaussianNetworkModel.__init__[0;34m(self, molecular_system, selection, structure_index, cutoff, syntax)[0m
[1;32m     31[0m [38;5;28mself[39m[38;5;241m.[39mcorrelation_matrix [38;5;241m=[39m [38;5;28;01mNone[39;00m
[1;32m     32[0m [38;5;28mself[39m[38;5;241m.[39minverse [38;5;241m=[39m [38;5;28;01mNone[39;00m
[0;32m---> 34[0m [38;5;28;43mself[39;49m[38;5;241;43m.[39;49m[43mmake_model[49m[43m([49m[43mselection[49m[38;5;241;43m=[39;49m[43mselection[49m[43m,[49m[43m [49m[43mcutoff[49m[38;5;241;43m=[39;49m[43mcutoff[49m[43m,[49m[43m [49m[43msyntax[49m[38;5;241;43m=[39;49m[43msyntax[49m[43m)[49m

File [0;32m~/micromamba-root/envs/docs/lib/python3.10/site-packages/openenm/gaussian_network_model.py:85[0m, in [0;36mGaussianNetworkModel.make_model[0;34m(self, selection, cutoff, syntax)[0m
[1;32m     82[0m bb[38;5;241m=[39m[38;5;241m0.0[39m
[1;32m     84[0m [38;5;28;01mfor[39;00m ii [38;5;129;01min[39;00m [38;5;28mrange[39m([38;5;28mself[39m[38;5;241m.[39mn_nodes):
[0;32m---> 85[0m     aa[38;5;241m+[39m[38;5;241m=[39m[38;5;28;43mself[39;49m[38;5;241;43m.[39;49m[43mb_factors_exp[49m[43m[[49m[43mii[49m[43m][49m[38;5;241m*[39mb_factors_unfitted[ii]
[1;32m     86[0m     bb[38;5;241m+[39m[38;5;241m=[39mb_factors_unfitted[ii][38;5;241m*[39mb_factors_unfitted[ii]
[1;32m     88[0m [38;5;28mself[39m[38;5;241m.[39mscaling_factor [38;5;241m=[39m aa[38;5;241m/[39mbb

[0;31mTypeError[0m: 'NoneType' object is not subscriptable

